<mujoco model="erobot">
  <compiler angle="radian" autolimits="true" />
  <option timestep="0.002" integrator="implicitfast" />
  <default>
    <default class="erobot">
      <default class="visual">
        <geom group="2" contype="0" conaffinity="0" density="0" />
      </default>
      <default class="collision">
        <geom group="3" contype="1" conaffinity="1" condim="3" friction="1.0 0.02 0.001" density="0" />
      </default>
    </default>
  </default>
  <asset>
    <material name="PA6_GF30" rgba="0.22 0.23 0.25 1" reflectance="0.3" />
    <material name="PC_ABS" rgba="0.95 0.45 0.13 1" reflectance="0.2" />
    <material name="TPU_SHORE_A95" rgba="0.07 0.07 0.08 1" reflectance="0.1" />
  </asset>
  <worldbody>
    <body name="pelvis" pos="0 0 0.918">
      <freejoint name="root" />
      <inertial pos="0 0 0" quat="0.707107 0 0 -0.707107" mass="0.808656" diaginertia="0.00346374 0.00508106 0.00551234" />
      <site name="imu_site" pos="0 0 0" size="0.01" />
      <geom name="pelvis_shell" class="visual" material="PA6_GF30" type="box" size="0.085 0.115 0.075" pos="0 0 0" />
      <body name="left_hip_pitch" pos="0 0.105 0">
        <inertial pos="0 0 0" quat="1 0 0 0" mass="1.03457" diaginertia="0.00044298 0.00044298 0.00044298" />
        <joint name="left_hip_pitch_joint" type="hinge" axis="0 1 0" range="-2 1" damping="2" armature="0.1" frictionloss="0.4" />
        <geom name="left_hip_pitch_shell" class="visual" material="PA6_GF30" type="sphere" size="0.06" pos="0 0 0" />
        <body name="left_hip_roll" pos="0 0 0">
          <inertial pos="0 0 0" quat="1 0 0 0" mass="1.03457" diaginertia="0.00044298 0.00044298 0.00044298" />
          <joint name="left_hip_roll_joint" type="hinge" axis="1 0 0" range="-0.2 0.5" damping="2" armature="0.1" frictionloss="0.4" />
          <geom name="left_hip_roll_shell" class="visual" material="PA6_GF30" type="sphere" size="0.06" pos="0 0 0" />
          <body name="left_hip_yaw" pos="0 0 0">
            <inertial pos="0 0 -0.127081" quat="0.707107 0 0.707107 -0" mass="1.31695" diaginertia="0.00268095 0.026933 0.026933" />
            <joint name="left_hip_yaw_joint" type="hinge" axis="0 0 1" range="-0.8 0.8" damping="1" armature="0.05" frictionloss="0.2" />
            <geom name="left_thigh_shell" class="visual" material="PA6_GF30" type="capsule" fromto="0 0 0 0 0 -0.42" size="0.058" />
            <body name="left_knee" pos="0 0 -0.42">
              <inertial pos="0 0 -0.0798658" quat="0.707107 0 0.707107 -0" mass="1.66951" diaginertia="0.00190588 0.0278597 0.0278597" />
              <joint name="left_knee_joint" type="hinge" axis="0 1 0" range="0 2.3" damping="2" armature="0.1" frictionloss="0.4" />
              <geom name="left_knee_shell" class="visual" material="PA6_GF30" type="sphere" size="0.06" pos="0 0 0" />
              <geom name="left_shank_shell" class="visual" material="PA6_GF30" type="capsule" fromto="0 0 0 0 0 -0.42" size="0.048" />
              <site name="left_toe_cable_shank" pos="-0.035 0 -0.06" size="0.004" rgba="0.1 0.1 0.1 1" />
              <body name="left_ankle_pitch" pos="0 0 -0.42">
                <inertial pos="0 0 0" quat="1 0 0 0" mass="0.648177" diaginertia="0.000213628 0.000213628 0.000213628" />
                <joint name="left_ankle_pitch_joint" type="hinge" axis="0 1 0" range="-0.9 0.5" damping="1" armature="0.05" frictionloss="0.2" />
                <geom name="left_ankle_pitch_shell" class="visual" material="PA6_GF30" type="sphere" size="0.05" pos="0 0 0" />
                <body name="left_ankle_roll" pos="0 0 0">
                  <inertial pos="0.00345366 0 -0.0205158" quat="0.618361 0.618361 0.342972 -0.342972" mass="0.990137" diaginertia="0.0011675 0.00146355 0.00184749" />
                  <joint name="left_ankle_roll_joint" type="hinge" axis="1 0 0" range="-0.3 0.3" damping="1" armature="0.05" frictionloss="0.2" />
                  <geom name="left_ankle_roll_shell" class="visual" material="PA6_GF30" type="sphere" size="0.05" pos="0 0 0" />
                  <geom name="left_foot_shell" class="visual" material="PA6_GF30" type="box" size="0.08 0.05 0.0225" pos="0.01 0 -0.0475" />
                  <geom name="left_foot_sole" class="visual" material="TPU_SHORE_A95" type="box" size="0.08 0.05 0.004" pos="0.01 0 -0.074" />
                  <geom name="left_foot_sole_col" class="collision" material="TPU_SHORE_A95" type="box" size="0.08 0.05 0.004" pos="0.01 0 -0.074" />
                  <geom name="left_ankle_pulley_geom" type="cylinder" fromto="-0.045 -0.018 -0.0475 -0.045 0.018 -0.0475" size="0.012" class="visual" material="PA6_GF30" contype="0" conaffinity="0" />
                  <site name="left_toe_pulley_side" pos="-0.065 0 -0.0475" size="0.004" rgba="0 0 0 0" />
                  <body name="left_toe" pos="0.09 0 -0.0475">
                    <inertial pos="0.0209139 0 -0.00571236" quat="0.994836 1.39498e-16 0.101499 -7.44156e-17" mass="0.35628" diaginertia="0.000208415 0.000302755 0.000404807" />
                    <joint name="left_toe_joint" type="hinge" axis="0 1 0" range="-0.6 0.2" damping="0.3" armature="0.02" frictionloss="0.1" stiffness="3.0" springref="0.0" />
                    <geom name="left_toe_shell" class="visual" material="PA6_GF30" type="box" size="0.04 0.05 0.0225" pos="0.04 0 0" />
                    <geom name="left_toe_sole" class="visual" material="TPU_SHORE_A95" type="box" size="0.04 0.05 0.004" pos="0.04 0 -0.0265" />
                    <geom name="left_toe_sole_col" class="collision" material="TPU_SHORE_A95" type="box" size="0.04 0.05 0.004" pos="0.04 0 -0.0265" />
                    <site name="left_toe_cable_anchor" pos="0.02 0 -0.025" size="0.004" rgba="0.1 0.1 0.1 1" />
                  </body>
                </body>
              </body>
            </body>
          </body>
        </body>
      </body>
      <body name="right_hip_pitch" pos="0 -0.105 0">
        <inertial pos="0 0 0" quat="1 0 0 0" mass="1.03457" diaginertia="0.00044298 0.00044298 0.00044298" />
        <joint name="right_hip_pitch_joint" type="hinge" axis="0 1 0" range="-2 1" damping="2" armature="0.1" frictionloss="0.4" />
        <geom name="right_hip_pitch_shell" class="visual" material="PA6_GF30" type="sphere" size="0.06" pos="0 0 0" />
        <body name="right_hip_roll" pos="0 0 0">
          <inertial pos="0 0 0" quat="1 0 0 0" mass="1.03457" diaginertia="0.00044298 0.00044298 0.00044298" />
          <joint name="right_hip_roll_joint" type="hinge" axis="1 0 0" range="-0.5 0.2" damping="2" armature="0.1" frictionloss="0.4" />
          <geom name="right_hip_roll_shell" class="visual" material="PA6_GF30" type="sphere" size="0.06" pos="0 0 0" />
          <body name="right_hip_yaw" pos="0 0 0">
            <inertial pos="0 0 -0.127081" quat="0.707107 0 0.707107 -0" mass="1.31695" diaginertia="0.00268095 0.026933 0.026933" />
            <joint name="right_hip_yaw_joint" type="hinge" axis="0 0 1" range="-0.8 0.8" damping="1" armature="0.05" frictionloss="0.2" />
            <geom name="right_thigh_shell" class="visual" material="PA6_GF30" type="capsule" fromto="0 0 0 0 0 -0.42" size="0.058" />
            <body name="right_knee" pos="0 0 -0.42">
              <inertial pos="0 0 -0.0798658" quat="0.707107 0 0.707107 -0" mass="1.66951" diaginertia="0.00190588 0.0278597 0.0278597" />
              <joint name="right_knee_joint" type="hinge" axis="0 1 0" range="0 2.3" damping="2" armature="0.1" frictionloss="0.4" />
              <geom name="right_knee_shell" class="visual" material="PA6_GF30" type="sphere" size="0.06" pos="0 0 0" />
              <geom name="right_shank_shell" class="visual" material="PA6_GF30" type="capsule" fromto="0 0 0 0 0 -0.42" size="0.048" />
              <site name="right_toe_cable_shank" pos="-0.035 0 -0.06" size="0.004" rgba="0.1 0.1 0.1 1" />
              <body name="right_ankle_pitch" pos="0 0 -0.42">
                <inertial pos="0 0 0" quat="1 0 0 0" mass="0.648177" diaginertia="0.000213628 0.000213628 0.000213628" />
                <joint name="right_ankle_pitch_joint" type="hinge" axis="0 1 0" range="-0.9 0.5" damping="1" armature="0.05" frictionloss="0.2" />
                <geom name="right_ankle_pitch_shell" class="visual" material="PA6_GF30" type="sphere" size="0.05" pos="0 0 0" />
                <body name="right_ankle_roll" pos="0 0 0">
                  <inertial pos="0.00345366 0 -0.0205158" quat="0.618361 0.618361 0.342972 -0.342972" mass="0.990137" diaginertia="0.0011675 0.00146355 0.00184749" />
                  <joint name="right_ankle_roll_joint" type="hinge" axis="1 0 0" range="-0.3 0.3" damping="1" armature="0.05" frictionloss="0.2" />
                  <geom name="right_ankle_roll_shell" class="visual" material="PA6_GF30" type="sphere" size="0.05" pos="0 0 0" />
                  <geom name="right_foot_shell" class="visual" material="PA6_GF30" type="box" size="0.08 0.05 0.0225" pos="0.01 0 -0.0475" />
                  <geom name="right_foot_sole" class="visual" material="TPU_SHORE_A95" type="box" size="0.08 0.05 0.004" pos="0.01 0 -0.074" />
                  <geom name="right_foot_sole_col" class="collision" material="TPU_SHORE_A95" type="box" size="0.08 0.05 0.004" pos="0.01 0 -0.074" />
                  <geom name="right_ankle_pulley_geom" type="cylinder" fromto="-0.045 -0.018 -0.0475 -0.045 0.018 -0.0475" size="0.012" class="visual" material="PA6_GF30" contype="0" conaffinity="0" />
                  <site name="right_toe_pulley_side" pos="-0.065 0 -0.0475" size="0.004" rgba="0 0 0 0" />
                  <body name="right_toe" pos="0.09 0 -0.0475">
                    <inertial pos="0.0209139 0 -0.00571236" quat="0.994836 1.39498e-16 0.101499 -7.44156e-17" mass="0.35628" diaginertia="0.000208415 0.000302755 0.000404807" />
                    <joint name="right_toe_joint" type="hinge" axis="0 1 0" range="-0.6 0.2" damping="0.3" armature="0.02" frictionloss="0.1" stiffness="3.0" springref="0.0" />
                    <geom name="right_toe_shell" class="visual" material="PA6_GF30" type="box" size="0.04 0.05 0.0225" pos="0.04 0 0" />
                    <geom name="right_toe_sole" class="visual" material="TPU_SHORE_A95" type="box" size="0.04 0.05 0.004" pos="0.04 0 -0.0265" />
                    <geom name="right_toe_sole_col" class="collision" material="TPU_SHORE_A95" type="box" size="0.04 0.05 0.004" pos="0.04 0 -0.0265" />
                    <site name="right_toe_cable_anchor" pos="0.02 0 -0.025" size="0.004" rgba="0.1 0.1 0.1 1" />
                  </body>
                </body>
              </body>
            </body>
          </body>
        </body>
      </body>
      <body name="torso" pos="0 0 0.06">
        <inertial pos="0 0 0.0757571" quat="1 0 0 0" mass="5.94445" diaginertia="0.0645322 0.0660633 0.0984288" />
        <joint name="waist_yaw_joint" type="hinge" axis="0 0 1" range="-1 1" damping="1" armature="0.05" frictionloss="0.2" />
        <geom name="torso_shell" class="visual" material="PA6_GF30" type="box" size="0.095 0.15 0.21" pos="0 0 0.21" />
        <body name="left_shoulder_pitch" pos="0 0.21 0.44">
          <inertial pos="0 0 0" quat="1 0 0 0" mass="0.60875" diaginertia="0.000147917 0.000147917 0.000147917" />
          <joint name="left_shoulder_pitch_joint" type="hinge" axis="0 1 0" range="-3 1.5" damping="1" armature="0.05" frictionloss="0.2" />
          <geom name="left_shoulder_shell" class="visual" material="PC_ABS" type="sphere" size="0.05" pos="0 0 0" />
          <body name="left_shoulder_roll" pos="0 0 0">
            <inertial pos="0 0 0" quat="1 0 0 0" mass="0.52" diaginertia="1e-07 1e-07 1e-07" />
            <joint name="left_shoulder_roll_joint" type="hinge" axis="1 0 0" range="-1.6 1.6" damping="1" armature="0.05" frictionloss="0.2" />
            <body name="left_shoulder_yaw" pos="0 0 0">
              <inertial pos="0 0 -0.0480067" quat="0.707107 0 0.707107 -0" mass="0.791362" diaginertia="0.000478683 0.00550713 0.00550713" />
              <joint name="left_shoulder_yaw_joint" type="hinge" axis="0 0 1" range="-1.6 1.6" damping="1" armature="0.05" frictionloss="0.2" />
              <geom name="left_upper_arm_shell" class="visual" material="PC_ABS" type="capsule" fromto="0 0 0 0 0 -0.28" size="0.042" />
              <body name="left_elbow" pos="0 0 -0.28">
                <inertial pos="0 0 -0.0335964" quat="0.707107 0 0.707107 -0" mass="0.820898" diaginertia="0.00042286 0.00413923 0.00413923" />
                <joint name="left_elbow_joint" type="hinge" axis="0 1 0" range="0 2.5" damping="1" armature="0.05" frictionloss="0.2" />
                <geom name="left_elbow_shell" class="visual" material="PC_ABS" type="sphere" size="0.05" pos="0 0 0" />
                <geom name="left_forearm_shell" class="visual" material="PC_ABS" type="capsule" fromto="0 0 0 0 0 -0.26" size="0.036" />
                <body name="left_wrist_yaw" pos="0 0 -0.26">
                  <inertial pos="0 0 -0.0340951" quat="0.5 -0.5 -0.5 -0.5" mass="0.398623" diaginertia="0.000229946 0.00119895 0.00127357" />
                  <joint name="left_wrist_yaw_joint" type="hinge" axis="0 0 1" range="-2 2" damping="0.5" armature="0.02" frictionloss="0.1" />
                  <geom name="left_wrist_shell" class="visual" material="PC_ABS" type="sphere" size="0.044" pos="0 0 0" />
                  <geom name="left_hand_shell" class="visual" material="PC_ABS" type="box" size="0.045 0.025 0.085" pos="0 0 -0.085" />
                </body>
              </body>
            </body>
          </body>
        </body>
        <body name="right_shoulder_pitch" pos="0 -0.21 0.44">
          <inertial pos="0 0 0" quat="1 0 0 0" mass="0.60875" diaginertia="0.000147917 0.000147917 0.000147917" />
          <joint name="right_shoulder_pitch_joint" type="hinge" axis="0 1 0" range="-3 1.5" damping="1" armature="0.05" frictionloss="0.2" />
          <geom name="right_shoulder_shell" class="visual" material="PC_ABS" type="sphere" size="0.05" pos="0 0 0" />
          <body name="right_shoulder_roll" pos="0 0 0">
            <inertial pos="0 0 0" quat="1 0 0 0" mass="0.52" diaginertia="1e-07 1e-07 1e-07" />
            <joint name="right_shoulder_roll_joint" type="hinge" axis="1 0 0" range="-1.6 1.6" damping="1" armature="0.05" frictionloss="0.2" />
            <body name="right_shoulder_yaw" pos="0 0 0">
              <inertial pos="0 0 -0.0480067" quat="0.707107 0 0.707107 -0" mass="0.791362" diaginertia="0.000478683 0.00550713 0.00550713" />
              <joint name="right_shoulder_yaw_joint" type="hinge" axis="0 0 1" range="-1.6 1.6" damping="1" armature="0.05" frictionloss="0.2" />
              <geom name="right_upper_arm_shell" class="visual" material="PC_ABS" type="capsule" fromto="0 0 0 0 0 -0.28" size="0.042" />
              <body name="right_elbow" pos="0 0 -0.28">
                <inertial pos="0 0 -0.0335964" quat="0.707107 0 0.707107 -0" mass="0.820898" diaginertia="0.00042286 0.00413923 0.00413923" />
                <joint name="right_elbow_joint" type="hinge" axis="0 1 0" range="0 2.5" damping="1" armature="0.05" frictionloss="0.2" />
                <geom name="right_elbow_shell" class="visual" material="PC_ABS" type="sphere" size="0.05" pos="0 0 0" />
                <geom name="right_forearm_shell" class="visual" material="PC_ABS" type="capsule" fromto="0 0 0 0 0 -0.26" size="0.036" />
                <body name="right_wrist_yaw" pos="0 0 -0.26">
                  <inertial pos="0 0 -0.0340951" quat="0.5 -0.5 -0.5 -0.5" mass="0.398623" diaginertia="0.000229946 0.00119895 0.00127357" />
                  <joint name="right_wrist_yaw_joint" type="hinge" axis="0 0 1" range="-2 2" damping="0.5" armature="0.02" frictionloss="0.1" />
                  <geom name="right_wrist_shell" class="visual" material="PC_ABS" type="sphere" size="0.044" pos="0 0 0" />
                  <geom name="right_hand_shell" class="visual" material="PC_ABS" type="box" size="0.045 0.025 0.085" pos="0 0 -0.085" />
                </body>
              </body>
            </body>
          </body>
        </body>
        <body name="neck" pos="0 0 0.51">
          <inertial pos="0 0 0.0110177" quat="0.707107 0 0.707107 -0" mass="0.2481" diaginertia="0.00012496 0.000159926 0.000159926" />
          <joint name="neck_yaw_joint" type="hinge" axis="0 0 1" range="-1.2 1.2" damping="0.5" armature="0.02" frictionloss="0.1" />
          <geom name="neck_shell" class="visual" material="PC_ABS" type="cylinder" fromto="0 0 0 0 0 0.07" size="0.04" />
          <body name="head" pos="0 0 0.07">
            <inertial pos="0 0 0.0642115" quat="1 0 0 0" mass="0.570602" diaginertia="0.00131878 0.00282485 0.00311136" />
            <joint name="neck_pitch_joint" type="hinge" axis="0 1 0" range="-0.6 0.6" damping="0.5" armature="0.02" frictionloss="0.1" />
            <geom name="head_shell" class="visual" material="PC_ABS" type="ellipsoid" size="0.09 0.08 0.115" pos="0 0 0.115" />
          </body>
        </body>
      </body>
    </body>
  </worldbody>
  <tendon>
    <spatial name="left_toe_tendon" width="0.003" rgba="0.05 0.05 0.05 1" limited="false">
      <site site="left_toe_cable_shank" />
      <geom geom="left_ankle_pulley_geom" sidesite="left_toe_pulley_side" />
      <site site="left_toe_cable_anchor" />
    </spatial>
    <spatial name="right_toe_tendon" width="0.003" rgba="0.05 0.05 0.05 1" limited="false">
      <site site="right_toe_cable_shank" />
      <geom geom="right_ankle_pulley_geom" sidesite="right_toe_pulley_side" />
      <site site="right_toe_cable_anchor" />
    </spatial>
  </tendon>
  <actuator>
    <position name="left_hip_pitch_act" joint="left_hip_pitch_joint" kp="320" ctrlrange="-2 1" forcerange="-120 120" />
    <position name="left_hip_roll_act" joint="left_hip_roll_joint" kp="320" ctrlrange="-0.2 0.5" forcerange="-120 120" />
    <position name="left_hip_yaw_act" joint="left_hip_yaw_joint" kp="140" ctrlrange="-0.8 0.8" forcerange="-24 24" />
    <position name="left_knee_act" joint="left_knee_joint" kp="320" ctrlrange="0 2.3" forcerange="-120 120" />
    <position name="left_ankle_pitch_act" joint="left_ankle_pitch_joint" kp="140" ctrlrange="-0.9 0.5" forcerange="-24 24" />
    <position name="left_ankle_roll_act" joint="left_ankle_roll_joint" kp="140" ctrlrange="-0.3 0.3" forcerange="-24 24" />
    <position name="right_hip_pitch_act" joint="right_hip_pitch_joint" kp="320" ctrlrange="-2 1" forcerange="-120 120" />
    <position name="right_hip_roll_act" joint="right_hip_roll_joint" kp="320" ctrlrange="-0.5 0.2" forcerange="-120 120" />
    <position name="right_hip_yaw_act" joint="right_hip_yaw_joint" kp="140" ctrlrange="-0.8 0.8" forcerange="-24 24" />
    <position name="right_knee_act" joint="right_knee_joint" kp="320" ctrlrange="0 2.3" forcerange="-120 120" />
    <position name="right_ankle_pitch_act" joint="right_ankle_pitch_joint" kp="140" ctrlrange="-0.9 0.5" forcerange="-24 24" />
    <position name="right_ankle_roll_act" joint="right_ankle_roll_joint" kp="140" ctrlrange="-0.3 0.3" forcerange="-24 24" />
    <position name="waist_yaw_act" joint="waist_yaw_joint" kp="140" ctrlrange="-1 1" forcerange="-24 24" />
    <position name="left_shoulder_pitch_act" joint="left_shoulder_pitch_joint" kp="140" ctrlrange="-3 1.5" forcerange="-24 24" />
    <position name="left_shoulder_roll_act" joint="left_shoulder_roll_joint" kp="140" ctrlrange="-1.6 1.6" forcerange="-24 24" />
    <position name="left_shoulder_yaw_act" joint="left_shoulder_yaw_joint" kp="140" ctrlrange="-1.6 1.6" forcerange="-24 24" />
    <position name="left_elbow_act" joint="left_elbow_joint" kp="140" ctrlrange="0 2.5" forcerange="-24 24" />
    <position name="left_wrist_yaw_act" joint="left_wrist_yaw_joint" kp="45" ctrlrange="-2 2" forcerange="-10 10" />
    <position name="right_shoulder_pitch_act" joint="right_shoulder_pitch_joint" kp="140" ctrlrange="-3 1.5" forcerange="-24 24" />
    <position name="right_shoulder_roll_act" joint="right_shoulder_roll_joint" kp="140" ctrlrange="-1.6 1.6" forcerange="-24 24" />
    <position name="right_shoulder_yaw_act" joint="right_shoulder_yaw_joint" kp="140" ctrlrange="-1.6 1.6" forcerange="-24 24" />
    <position name="right_elbow_act" joint="right_elbow_joint" kp="140" ctrlrange="0 2.5" forcerange="-24 24" />
    <position name="right_wrist_yaw_act" joint="right_wrist_yaw_joint" kp="45" ctrlrange="-2 2" forcerange="-10 10" />
    <position name="neck_yaw_act" joint="neck_yaw_joint" kp="45" ctrlrange="-1.2 1.2" forcerange="-10 10" />
    <position name="neck_pitch_act" joint="neck_pitch_joint" kp="45" ctrlrange="-0.6 0.6" forcerange="-10 10" />
    <motor name="left_toe_act" tendon="left_toe_tendon" ctrlrange="0 60" gear="1" />
    <motor name="right_toe_act" tendon="right_toe_tendon" ctrlrange="0 60" gear="1" />
  </actuator>
  <sensor>
    <framequat name="imu_quat" objtype="body" objname="pelvis" />
    <gyro name="imu_gyro" site="imu_site" />
    <accelerometer name="imu_acc" site="imu_site" />
    <jointpos name="left_hip_pitch_joint_pos" joint="left_hip_pitch_joint" />
    <jointvel name="left_hip_pitch_joint_vel" joint="left_hip_pitch_joint" />
    <jointpos name="left_hip_roll_joint_pos" joint="left_hip_roll_joint" />
    <jointvel name="left_hip_roll_joint_vel" joint="left_hip_roll_joint" />
    <jointpos name="left_hip_yaw_joint_pos" joint="left_hip_yaw_joint" />
    <jointvel name="left_hip_yaw_joint_vel" joint="left_hip_yaw_joint" />
    <jointpos name="left_knee_joint_pos" joint="left_knee_joint" />
    <jointvel name="left_knee_joint_vel" joint="left_knee_joint" />
    <jointpos name="left_ankle_pitch_joint_pos" joint="left_ankle_pitch_joint" />
    <jointvel name="left_ankle_pitch_joint_vel" joint="left_ankle_pitch_joint" />
    <jointpos name="left_ankle_roll_joint_pos" joint="left_ankle_roll_joint" />
    <jointvel name="left_ankle_roll_joint_vel" joint="left_ankle_roll_joint" />
    <jointpos name="left_toe_joint_pos" joint="left_toe_joint" />
    <jointvel name="left_toe_joint_vel" joint="left_toe_joint" />
    <jointpos name="right_hip_pitch_joint_pos" joint="right_hip_pitch_joint" />
    <jointvel name="right_hip_pitch_joint_vel" joint="right_hip_pitch_joint" />
    <jointpos name="right_hip_roll_joint_pos" joint="right_hip_roll_joint" />
    <jointvel name="right_hip_roll_joint_vel" joint="right_hip_roll_joint" />
    <jointpos name="right_hip_yaw_joint_pos" joint="right_hip_yaw_joint" />
    <jointvel name="right_hip_yaw_joint_vel" joint="right_hip_yaw_joint" />
    <jointpos name="right_knee_joint_pos" joint="right_knee_joint" />
    <jointvel name="right_knee_joint_vel" joint="right_knee_joint" />
    <jointpos name="right_ankle_pitch_joint_pos" joint="right_ankle_pitch_joint" />
    <jointvel name="right_ankle_pitch_joint_vel" joint="right_ankle_pitch_joint" />
    <jointpos name="right_ankle_roll_joint_pos" joint="right_ankle_roll_joint" />
    <jointvel name="right_ankle_roll_joint_vel" joint="right_ankle_roll_joint" />
    <jointpos name="right_toe_joint_pos" joint="right_toe_joint" />
    <jointvel name="right_toe_joint_vel" joint="right_toe_joint" />
    <jointpos name="waist_yaw_joint_pos" joint="waist_yaw_joint" />
    <jointvel name="waist_yaw_joint_vel" joint="waist_yaw_joint" />
    <jointpos name="left_shoulder_pitch_joint_pos" joint="left_shoulder_pitch_joint" />
    <jointvel name="left_shoulder_pitch_joint_vel" joint="left_shoulder_pitch_joint" />
    <jointpos name="left_shoulder_roll_joint_pos" joint="left_shoulder_roll_joint" />
    <jointvel name="left_shoulder_roll_joint_vel" joint="left_shoulder_roll_joint" />
    <jointpos name="left_shoulder_yaw_joint_pos" joint="left_shoulder_yaw_joint" />
    <jointvel name="left_shoulder_yaw_joint_vel" joint="left_shoulder_yaw_joint" />
    <jointpos name="left_elbow_joint_pos" joint="left_elbow_joint" />
    <jointvel name="left_elbow_joint_vel" joint="left_elbow_joint" />
    <jointpos name="left_wrist_yaw_joint_pos" joint="left_wrist_yaw_joint" />
    <jointvel name="left_wrist_yaw_joint_vel" joint="left_wrist_yaw_joint" />
    <jointpos name="right_shoulder_pitch_joint_pos" joint="right_shoulder_pitch_joint" />
    <jointvel name="right_shoulder_pitch_joint_vel" joint="right_shoulder_pitch_joint" />
    <jointpos name="right_shoulder_roll_joint_pos" joint="right_shoulder_roll_joint" />
    <jointvel name="right_shoulder_roll_joint_vel" joint="right_shoulder_roll_joint" />
    <jointpos name="right_shoulder_yaw_joint_pos" joint="right_shoulder_yaw_joint" />
    <jointvel name="right_shoulder_yaw_joint_vel" joint="right_shoulder_yaw_joint" />
    <jointpos name="right_elbow_joint_pos" joint="right_elbow_joint" />
    <jointvel name="right_elbow_joint_vel" joint="right_elbow_joint" />
    <jointpos name="right_wrist_yaw_joint_pos" joint="right_wrist_yaw_joint" />
    <jointvel name="right_wrist_yaw_joint_vel" joint="right_wrist_yaw_joint" />
    <jointpos name="neck_yaw_joint_pos" joint="neck_yaw_joint" />
    <jointvel name="neck_yaw_joint_vel" joint="neck_yaw_joint" />
    <jointpos name="neck_pitch_joint_pos" joint="neck_pitch_joint" />
    <jointvel name="neck_pitch_joint_vel" joint="neck_pitch_joint" />
  </sensor>
  <keyframe>
    <key name="home" qpos="0 0 0.918 1 0 0 0 0 0 0 0 0 0 0 0 -0 -0 0 0 -0 0 0 0 0 0 0.3 0 0 -0 -0 0.3 -0 0 0" ctrl="0 0 0 0 0 0 0 -0 -0 0 0 -0 0 0 0 0 0.3 0 0 -0 -0 0.3 -0 0 0 0 0" />
  </keyframe>
</mujoco>